<?xml version="1.0" encoding="UTF-8"?>
<testng-results ignored="0" total="10" passed="7" failed="3" skipped="0">
  <reporter-output>
  </reporter-output>
  <suite started-at="2024-12-15T11:55:47 IST" name="Default suite" finished-at="2024-12-15T11:57:08 IST" duration-ms="80706">
    <groups>
    </groups>
    <test started-at="2024-12-15T11:55:47 IST" name="Default test" finished-at="2024-12-15T11:57:08 IST" duration-ms="80706">
      <class name="Capstone.Ques1">
        <test-method signature="AddnewUser()[pri:1, instance:Capstone.Ques1@4802796d]" started-at="2024-12-15T11:55:47 IST" name="AddnewUser" finished-at="2024-12-15T11:55:55 IST" duration-ms="8042" status="PASS">
          <reporter-output>
          </reporter-output>
        </test-method> <!-- AddnewUser -->
        <test-method signature="GetUserProfile()[pri:2, instance:Capstone.Ques1@4802796d]" started-at="2024-12-15T11:55:55 IST" name="GetUserProfile" finished-at="2024-12-15T11:55:57 IST" duration-ms="1241" status="PASS">
          <reporter-output>
          </reporter-output>
        </test-method> <!-- GetUserProfile -->
        <test-method signature="UpdateUser()[pri:3, instance:Capstone.Ques1@4802796d]" started-at="2024-12-15T11:55:57 IST" name="UpdateUser" finished-at="2024-12-15T11:55:58 IST" duration-ms="1231" status="PASS">
          <reporter-output>
          </reporter-output>
        </test-method> <!-- UpdateUser -->
        <test-method signature="LoginUser()[pri:4, instance:Capstone.Ques1@4802796d]" started-at="2024-12-15T11:55:58 IST" name="LoginUser" finished-at="2024-12-15T11:55:59 IST" duration-ms="1298" status="PASS">
          <reporter-output>
          </reporter-output>
        </test-method> <!-- LoginUser -->
        <test-method signature="Addcontact()[pri:5, instance:Capstone.Ques1@4802796d]" started-at="2024-12-15T11:55:59 IST" name="Addcontact" finished-at="2024-12-15T11:56:00 IST" duration-ms="1210" status="FAIL">
          <exception class="java.lang.AssertionError">
            <message>
              <![CDATA[expected [201] but found [400]]]>
            </message>
            <full-stacktrace>
              <![CDATA[java.lang.AssertionError: expected [201] but found [400]
at org.testng.Assert.fail(Assert.java:110)
at org.testng.Assert.failNotEquals(Assert.java:1577)
at org.testng.Assert.assertEqualsImpl(Assert.java:149)
at org.testng.Assert.assertEquals(Assert.java:131)
at org.testng.Assert.assertEquals(Assert.java:1418)
at org.testng.Assert.assertEquals(Assert.java:1382)
at org.testng.Assert.assertEquals(Assert.java:1428)
at Capstone.Ques1.Addcontact(Ques1.java:156)
at java.base/jdk.internal.reflect.DirectMethodHandleAccessor.invoke(DirectMethodHandleAccessor.java:103)
at java.base/java.lang.reflect.Method.invoke(Method.java:580)
at org.testng.internal.invokers.MethodInvocationHelper.invokeMethod(MethodInvocationHelper.java:139)
at org.testng.internal.invokers.TestInvoker.invokeMethod(TestInvoker.java:677)
at org.testng.internal.invokers.TestInvoker.invokeTestMethod(TestInvoker.java:221)
at org.testng.internal.invokers.MethodRunner.runInSequence(MethodRunner.java:50)
at org.testng.internal.invokers.TestInvoker$MethodInvocationAgent.invoke(TestInvoker.java:969)
at org.testng.internal.invokers.TestInvoker.invokeTestMethods(TestInvoker.java:194)
at org.testng.internal.invokers.TestMethodWorker.invokeTestMethods(TestMethodWorker.java:148)
at org.testng.internal.invokers.TestMethodWorker.run(TestMethodWorker.java:128)
at java.base/java.util.ArrayList.forEach(ArrayList.java:1597)
at org.testng.TestRunner.privateRun(TestRunner.java:829)
at org.testng.TestRunner.run(TestRunner.java:602)
at org.testng.SuiteRunner.runTest(SuiteRunner.java:437)
at org.testng.SuiteRunner.runSequentially(SuiteRunner.java:431)
at org.testng.SuiteRunner.privateRun(SuiteRunner.java:391)
at org.testng.SuiteRunner.run(SuiteRunner.java:330)
at org.testng.SuiteRunnerWorker.runSuite(SuiteRunnerWorker.java:52)
at org.testng.SuiteRunnerWorker.run(SuiteRunnerWorker.java:95)
at org.testng.TestNG.runSuitesSequentially(TestNG.java:1256)
at org.testng.TestNG.runSuitesLocally(TestNG.java:1176)
at org.testng.TestNG.runSuites(TestNG.java:1099)
at org.testng.TestNG.run(TestNG.java:1067)
at org.testng.remote.AbstractRemoteTestNG.run(AbstractRemoteTestNG.java:115)
at org.testng.remote.RemoteTestNG.initAndRun(RemoteTestNG.java:293)
at org.testng.remote.RemoteTestNG.main(RemoteTestNG.java:91)
]]>
            </full-stacktrace>
          </exception> <!-- java.lang.AssertionError -->
          <reporter-output>
          </reporter-output>
        </test-method> <!-- Addcontact -->
        <test-method signature="Getcontactlist()[pri:6, instance:Capstone.Ques1@4802796d]" started-at="2024-12-15T11:56:00 IST" name="Getcontactlist" finished-at="2024-12-15T11:56:02 IST" duration-ms="1191" status="PASS">
          <reporter-output>
          </reporter-output>
        </test-method> <!-- Getcontactlist -->
        <test-method signature="Getcontact()[pri:7, instance:Capstone.Ques1@4802796d]" started-at="2024-12-15T11:56:02 IST" name="Getcontact" finished-at="2024-12-15T11:56:03 IST" duration-ms="1204" status="PASS">
          <reporter-output>
          </reporter-output>
        </test-method> <!-- Getcontact -->
        <test-method signature="Updatecontact()[pri:8, instance:Capstone.Ques1@4802796d]" started-at="2024-12-15T11:56:03 IST" name="Updatecontact" finished-at="2024-12-15T11:56:35 IST" duration-ms="31897" status="FAIL">
          <exception class="java.lang.AssertionError">
            <message>
              <![CDATA[expected [200] but found [503]]]>
            </message>
            <full-stacktrace>
              <![CDATA[java.lang.AssertionError: expected [200] but found [503]
at org.testng.Assert.fail(Assert.java:110)
at org.testng.Assert.failNotEquals(Assert.java:1577)
at org.testng.Assert.assertEqualsImpl(Assert.java:149)
at org.testng.Assert.assertEquals(Assert.java:131)
at org.testng.Assert.assertEquals(Assert.java:1418)
at org.testng.Assert.assertEquals(Assert.java:1382)
at org.testng.Assert.assertEquals(Assert.java:1428)
at Capstone.Ques1.Updatecontact(Ques1.java:231)
at java.base/jdk.internal.reflect.DirectMethodHandleAccessor.invoke(DirectMethodHandleAccessor.java:103)
at java.base/java.lang.reflect.Method.invoke(Method.java:580)
at org.testng.internal.invokers.MethodInvocationHelper.invokeMethod(MethodInvocationHelper.java:139)
at org.testng.internal.invokers.TestInvoker.invokeMethod(TestInvoker.java:677)
at org.testng.internal.invokers.TestInvoker.invokeTestMethod(TestInvoker.java:221)
at org.testng.internal.invokers.MethodRunner.runInSequence(MethodRunner.java:50)
at org.testng.internal.invokers.TestInvoker$MethodInvocationAgent.invoke(TestInvoker.java:969)
at org.testng.internal.invokers.TestInvoker.invokeTestMethods(TestInvoker.java:194)
at org.testng.internal.invokers.TestMethodWorker.invokeTestMethods(TestMethodWorker.java:148)
at org.testng.internal.invokers.TestMethodWorker.run(TestMethodWorker.java:128)
at java.base/java.util.ArrayList.forEach(ArrayList.java:1597)
at org.testng.TestRunner.privateRun(TestRunner.java:829)
at org.testng.TestRunner.run(TestRunner.java:602)
at org.testng.SuiteRunner.runTest(SuiteRunner.java:437)
at org.testng.SuiteRunner.runSequentially(SuiteRunner.java:431)
at org.testng.SuiteRunner.privateRun(SuiteRunner.java:391)
at org.testng.SuiteRunner.run(SuiteRunner.java:330)
at org.testng.SuiteRunnerWorker.runSuite(SuiteRunnerWorker.java:52)
at org.testng.SuiteRunnerWorker.run(SuiteRunnerWorker.java:95)
at org.testng.TestNG.runSuitesSequentially(TestNG.java:1256)
at org.testng.TestNG.runSuitesLocally(TestNG.java:1176)
at org.testng.TestNG.runSuites(TestNG.java:1099)
at org.testng.TestNG.run(TestNG.java:1067)
at org.testng.remote.AbstractRemoteTestNG.run(AbstractRemoteTestNG.java:115)
at org.testng.remote.RemoteTestNG.initAndRun(RemoteTestNG.java:293)
at org.testng.remote.RemoteTestNG.main(RemoteTestNG.java:91)
]]>
            </full-stacktrace>
          </exception> <!-- java.lang.AssertionError -->
          <reporter-output>
          </reporter-output>
        </test-method> <!-- Updatecontact -->
        <test-method signature="Updatecontactpartial()[pri:9, instance:Capstone.Ques1@4802796d]" started-at="2024-12-15T11:56:35 IST" name="Updatecontactpartial" finished-at="2024-12-15T11:57:06 IST" duration-ms="31480" status="FAIL">
          <exception class="java.lang.AssertionError">
            <message>
              <![CDATA[expected [200] but found [503]]]>
            </message>
            <full-stacktrace>
              <![CDATA[java.lang.AssertionError: expected [200] but found [503]
at org.testng.Assert.fail(Assert.java:110)
at org.testng.Assert.failNotEquals(Assert.java:1577)
at org.testng.Assert.assertEqualsImpl(Assert.java:149)
at org.testng.Assert.assertEquals(Assert.java:131)
at org.testng.Assert.assertEquals(Assert.java:1418)
at org.testng.Assert.assertEquals(Assert.java:1382)
at org.testng.Assert.assertEquals(Assert.java:1428)
at Capstone.Ques1.Updatecontactpartial(Ques1.java:269)
at java.base/jdk.internal.reflect.DirectMethodHandleAccessor.invoke(DirectMethodHandleAccessor.java:103)
at java.base/java.lang.reflect.Method.invoke(Method.java:580)
at org.testng.internal.invokers.MethodInvocationHelper.invokeMethod(MethodInvocationHelper.java:139)
at org.testng.internal.invokers.TestInvoker.invokeMethod(TestInvoker.java:677)
at org.testng.internal.invokers.TestInvoker.invokeTestMethod(TestInvoker.java:221)
at org.testng.internal.invokers.MethodRunner.runInSequence(MethodRunner.java:50)
at org.testng.internal.invokers.TestInvoker$MethodInvocationAgent.invoke(TestInvoker.java:969)
at org.testng.internal.invokers.TestInvoker.invokeTestMethods(TestInvoker.java:194)
at org.testng.internal.invokers.TestMethodWorker.invokeTestMethods(TestMethodWorker.java:148)
at org.testng.internal.invokers.TestMethodWorker.run(TestMethodWorker.java:128)
at java.base/java.util.ArrayList.forEach(ArrayList.java:1597)
at org.testng.TestRunner.privateRun(TestRunner.java:829)
at org.testng.TestRunner.run(TestRunner.java:602)
at org.testng.SuiteRunner.runTest(SuiteRunner.java:437)
at org.testng.SuiteRunner.runSequentially(SuiteRunner.java:431)
at org.testng.SuiteRunner.privateRun(SuiteRunner.java:391)
at org.testng.SuiteRunner.run(SuiteRunner.java:330)
at org.testng.SuiteRunnerWorker.runSuite(SuiteRunnerWorker.java:52)
at org.testng.SuiteRunnerWorker.run(SuiteRunnerWorker.java:95)
at org.testng.TestNG.runSuitesSequentially(TestNG.java:1256)
at org.testng.TestNG.runSuitesLocally(TestNG.java:1176)
at org.testng.TestNG.runSuites(TestNG.java:1099)
at org.testng.TestNG.run(TestNG.java:1067)
at org.testng.remote.AbstractRemoteTestNG.run(AbstractRemoteTestNG.java:115)
at org.testng.remote.RemoteTestNG.initAndRun(RemoteTestNG.java:293)
at org.testng.remote.RemoteTestNG.main(RemoteTestNG.java:91)
]]>
            </full-stacktrace>
          </exception> <!-- java.lang.AssertionError -->
          <reporter-output>
          </reporter-output>
        </test-method> <!-- Updatecontactpartial -->
        <test-method signature="Logout()[pri:10, instance:Capstone.Ques1@4802796d]" started-at="2024-12-15T11:57:06 IST" name="Logout" finished-at="2024-12-15T11:57:08 IST" duration-ms="1781" status="PASS">
          <reporter-output>
          </reporter-output>
        </test-method> <!-- Logout -->
      </class> <!-- Capstone.Ques1 -->
    </test> <!-- Default test -->
  </suite> <!-- Default suite -->
</testng-results>
